Workbook

Sheet Riepilogo di esportazione
B3: Questo documento è stato esportato da Numbers. Tutte le tabelle sono state convertite in un foglio di lavoro di Excel. Tutti gli altri oggetti di ciascun foglio di Numbers sono stati collocati in fogli di lavoro separati. Nota che i calcoli delle formule potrebbero differire in Excel.
B7: Nome del foglio di Numbers | C7: Nome della tabella di Numbers | D7: Nome foglio di lavoro Excel
B9: WBS
C10: Tabella 1 | D10: WBS
B11: ELB_Esecutivo
C12: Tabella 1 | D12: ELB_Esecutivo

Sheet WBS
A1: CODICE PROGETTO | B1: STATO DEL PROGETTO | D1: AMBITO | F1: EDIFICIO | H1: LIVELLO | J1: TIPO DI ELABORATO
A2: 25007 | B2: PP | C2: Progetto Preliminare | D2: 0G | E2: Generali | F2: GN | G2: Generale | H2: GE | I2: Generale | J2: ELB | K2: Elenco elaborati
B3: PD | C3: Progetto Definitivo | D3: 1A | E3: Architettonici | F3: A | G3: Corpo A | H3: P0 | I3: Piano Terra | J3: REL | K3: Relazione
B4: PE | C4: Progetto Esecutivo | D4: 2S | E4: Strutturali | F4: B | G4: Corpo B | H4: P1 | I4: Piano Primo | J4: CAL | K4: Calcoli
B5: IN | C5: Piano di indagini | D5: 3I | E5: Impianti | F5: Z | G5: Colletto | H5: P2 | I5: Piano Secondo | J5: SCH | K5: Schema
D6: 4S | E6: Sicurezza | F6: C | G6: Corpo C | H6: P3 | I6: Piano Terzo | J6: VAL | K6: Valutazioni
D7: 7R | E7: Rilievo | F7: D | G7: Corpo D | H7: P4 | I7: Piano Terzo | J7: CME | K7: Computi Metrici
D8: 8PI | E8: Prevenzione Incendi | F8: F | G8: Corpo F | H8: P5 | I8: Piano Terzo | J8: EPU | K8: Elenco prezzi ed Analisi
F9: G | G9: Corpo G | H9: P6 | I9: Piano Terzo | J9: ANP | K9: Analisi prezzi
F10: H | G10: Corpo H | H10: P7 | I10: Piano Terzo | J10: CRO | K10: Cronoprogramma
F11: BFG | G11: Corpi BFG | H11: P8 | I11: Piano Terzo | J11: DIS | K11: Disciplinare
F12: CDEH | G12: Corpi CDEH | H12: P9 | I12: Piano Terzo | J12: CSA | K12: Capitolato Speciale
H13: P10 | I13: Piano Terzo | J13: QTE | K13: Quadro tecnico economico
H14: P11 | I14: Piano Terzo | J14: PLN | K14: Planimetria
H15: P12 | I15: Piano Terzo | J15: PNT | K15: Piante
H16: P13 | I16: Piano Terzo | J16: SEZ | K16: Sezioni
H17: P14 | I17: Piano Terzo | J17: PRO | K17: Prospetti
H18: P15 | I18: Piano Terzo | J18: ABA | K18: Abaco
H19: P16 | I19: Piano Terzo | J19: CRP | K19: Carpenterie
H20: P17 | I20: Piano Terzo | J20: ARM | K20: Armature
H21: P18 | I21: Piano Terzo | J21: MET | K21: Carpenteria Metallica
H22: P19 | I22: Piano Terzo | J22: DET | K22: Dettagli
H23: PI | I23: Piano Interrato | J23: INF | K23: Gestione informativa
H24: PR | I24: Piano rialzato | J24: CAP | K24: Capitolato Speciale
H25: PC | I25: Copertura | J25: SCC | K25: Schema di contratto
J26: TIP | K26: Tipologico

Sheet ELB_Esecutivo
A1: 25007_EX ARLECCHINO SITO IN PIAZZA CASTRUCCIO CASTRACANI A LIDO DI CAMAIORE_ | O1: Relazione/Tavola | P1: Copertina/Cartiglio | Q1: Ultima verifica | R1: Consegnato | S1: Note
A2: TW1923
B3: Disciplina | C3: Progetto | D3: Fase | E3: Disc. | F3: Edificio | G3: Liv. | H3: Tipo | I3: Prog. | J3: Rev | K3: Codice Elaborato | L3: Titolo Elaborato | M3: Scala | N3: Data consegna/revisione
B4: ELABORATI GENERALI | C4: 25007 | D4: PE | E4: 0G | F4: GN | G4: GE | H4: ELB | I4: 000 | J4: 00 | K4: =CONCATENATE(D4,".",E4,".",F4,".",G4,".",H4,".",I4,".",J4) -> PE.0G.GN.GE.ELB.000.00 | L4: Elenco degli elaborati | M4: -
B5: ELABORATI GENERALI | C5: 25007 | D5: PE | E5: 0G | F5: GN | G5: GE | H5: REL | I5: 001 | J5: 00 | K5: =CONCATENATE(D5,".",E5,".",F5,".",G5,".",H5,".",I5,".",J5) -> PE.0G.GN.GE.REL.001.00 | L5: Relazione generale | M5: -
B6: ELABORATI GENERALI | C6: 25007 | D6: PE | E6: 0G | F6: GN | G6: GE | H6: REL | I6: 002 | J6: 00 | K6: =CONCATENATE(D6,".",E6,".",F6,".",G6,".",H6,".",I6,".",J6) -> PE.0G.GN.GE.REL.002.00 | L6: Relazione sui Criteri Ambientali Minimi (CAM) | M6: -
B7: ELABORATI GENERALI | C7: 25007 | D7: PE | E7: 0G | F7: GN | G7: GE | H7: ELB | I7: 003 | J7: 00 | K7: =CONCATENATE(D7,".",E7,".",F7,".",G7,".",H7,".",I7,".",J7) -> PE.0G.GN.GE.ELB.003.00 | L7: Allegati CAM | M7: -
B8: ELABORATI GENERALI | C8: 25007 | D8: PE | E8: 0G | F8: GN | G8: GE | H8: REL | I8: 004 | J8: 00 | K8: =CONCATENATE(D8,".",E8,".",F8,".",G8,".",H8,".",I8,".",J8) -> PE.0G.GN.GE.REL.004.00 | L8: Relazione specialistica DNSH | M8: -
B9: ELABORATI GENERALI | C9: 25007 | D9: PE | E9: 0G | F9: GN | G9: GE | H9: REL | I9: 005 | J9: 00 | K9: =CONCATENATE(D9,".",E9,".",F9,".",G9,".",H9,".",I9,".",J9) -> PE.0G.GN.GE.REL.005.00 | L9: Relazione sulla gestione delle materie e rocce da scavo | M9: -
B10: ELABORATI GENERALI | C10: 25007 | D10: PE | E10: 0G | F10: GN | G10: GE | H10: REL | I10: 006 | J10: 00 | K10: =CONCATENATE(D10,".",E10,".",F10,".",G10,".",H10,".",I10,".",J10) -> PE.0G.GN.GE.REL.006.00 | L10: Relazione sulla prevenzione incendi | M10: -
B11: ELABORATI GENERALI | C11: 25007 | D11: PE | E11: 0G | F11: GN | G11: GE | H11: REL | I11: 007 | J11: 00 | K11: =CONCATENATE(D11,".",E11,".",F11,".",G11,".",H11,".",I11,".",J11) -> PE.0G.GN.GE.REL.007.00 | L11: Relazione requisiti acustici passivi | M11: -
B12: ELABORATI GENERALI | C12: 25007 | D12: PE | E12: 0G | F12: GN | G12: GE | H12: REL | I12: 008 | J12: 00 | K12: =CONCATENATE(D12,".",E12,".",F12,".",G12,".",H12,".",I12,".",J12) -> PE.0G.GN.GE.REL.008.00 | L12: Relazione geologica | M12: -
B13: ELABORATI GENERALI | C13: 25007 | D13: PE | E13: 0G | F13: GN | G13: GE | H13: ELB | I13: 009 | J13: 00 | K13: =CONCATENATE(D13,".",E13,".",F13,".",G13,".",H13,".",I13,".",J13) -> PE.0G.GN.GE.ELB.009.00 | L13: Piano di manutenzione | M13: -
B14: ELABORATI GENERALI | C14: 25007 | D14: PE | E14: 0G | F14: GN | G14: GE | H14: CRO | I14: 010 | J14: 00 | K14: =CONCATENATE(D14,".",E14,".",F14,".",G14,".",H14,".",I14,".",J14) -> PE.0G.GN.GE.CRO.010.00 | L14: Cronoprogramma dei lavori | M14: -
B15: ELABORATI GENERALI | C15: 25007 | D15: PE | E15: 0G | F15: GN | G15: GE | H15: QTE | I15: 011 | J15: 00 | K15: =CONCATENATE(D15,".",E15,".",F15,".",G15,".",H15,".",I15,".",J15) -> PE.0G.GN.GE.QTE.011.00 | L15: Quadro tecnico economico | M15: -
... B20: ELABORATI GENERALI | C20: 25007 | D20: PE | E20: 0G | F20: GN | G20: GE | H20: CME | I20: 016 | J20: 00 | K20: =CONCATENATE(D20,".",E20,".",F20,".",G20,".",H20,".",I20,".",J20) -> PE.0G.GN.GE.CME.016.00 | L20: Computo metrico estimativo_Oneri della sicurezza | M20: -
B21: ELABORATI GENERALI | C21: 25007 | D21: PE | E21: 0G | F21: GN | G21: GE | H21: CME | I21: 017 | J21: 00 | K21: =CONCATENATE(D21,".",E21,".",F21,".",G21,".",H21,".",I21,".",J21) -> PE.0G.GN.GE.CME.017.00 | L21: Quadro di incidenza della manodopera_Oneri della sicurezza
A22: ELABORATI DESCRITTIVI DELLE OPERE ARCHITETTONICHE
B23: ELABORATI GENERALI | C23: 25007 | D23: PE | E23: 1A | F23: GN | G23: GE | H23: REL | I23: 100 | J23: 00 | K23: =CONCATENATE(D23,".",E23,".",F23,".",G23,".",H23,".",I23,".",J23) -> PE.1A.GN.GE.REL.100.00 | L23: Relazione tecnica delle opere architettoniche e requisiti igienico sanitari | M23: -
B24: ELABORATI GENERALI | C24: 25007 | D24: PE | E24: 1A | F24: GN | G24: GE | H24: REL | I24: 101 | J24: 00 | K24: =CONCATENATE(D24,".",E24,".",F24,".",G24,".",H24,".",I24,".",J24) -> PE.1A.GN.GE.REL.101.00 | L24: Relazione sul superamento delle barriere architettoniche | M24: -
B25: ELABORATI GENERALI | C25: 25007 | D25: PE | E25: 1A | F25: GN | G25: GE | H25: CAP | I25: 102 | J25: 00 | K25: =CONCATENATE(D25,".",E25,".",F25,".",G25,".",H25,".",I25,".",J25) -> PE.1A.GN.GE.CAP.102.00 | L25: Capitolato speciale d'appalto - Parte tecnica - Opere edili | M25: -
B26: ELABORATI GENERALI | C26: 25007 | D26: PE | E26: 1A | F26: GN | G26: GE | H26: CME | I26: 103 | J26: 00 | K26: =CONCATENATE(D26,".",E26,".",F26,".",G26,".",H26,".",I26,".",J26) -> PE.1A.GN.GE.CME.103.00 | L26: Computo metrico estimativo - opere architettoniche
B27: ELABORATI GENERALI | C27: 25007 | D27: PE | E27: 1A | F27: GN | G27: GE | H27: CME | I27: 104 | J27: 00 | K27: =CONCATENATE(D27,".",E27,".",F27,".",G27,".",H27,".",I27,".",J27) -> PE.1A.GN.GE.CME.104.00 | L27: Quadro di incidenza della manodopera - opere architettoniche
B28: ELABORATI GENERALI | C28: 25007 | D28: PE | E28: 1A | F28: GN | G28: GE | H28: EPU | I28: 105 | J28: 00 | K28: =CONCATENATE(D28,".",E28,".",F28,".",G28,".",H28,".",I28,".",J28) -> PE.1A.GN.GE.EPU.105.00 | L28: Elenco ed analisi prezzi unitari - opere architettoniche
B29: ELABORATI GENERALI | C29: 25007 | D29: PE | E29: 1A | F29: GN | G29: GE | H29: ELB | I29: 106 | J29: 00 | K29: =CONCATENATE(D29,".",E29,".",F29,".",G29,".",H29,".",I29,".",J29) -> PE.1A.GN.GE.ELB.106.00 | L29: Quadro comparativo: PFTE e PE - opere architettoniche
A30: ELABORATI DESCRITTIVI DELLE OPERE STRUTTURALI
B31: ELABORATI GENERALI | C31: 25007 | D31: PE | E31: 2S | F31: GN | G31: GE | H31: REL | I31: 200 | J31: 00 | K31: =CONCATENATE(D31,".",E31,".",F31,".",G31,".",H31,".",I31,".",J31) -> PE.2S.GN.GE.REL.200.00 | L31: Relazione tecnica generale delle opere strutturali | M31: -
B32: ELABORATI GENERALI | C32: 25007 | D32: PE | E32: 2S | F32: GN | G32: GE | H32: REL | I32: 201 | J32: 00 | K32: =CONCATENATE(D32,".",E32,".",F32,".",G32,".",H32,".",I32,".",J32) -> PE.2S.GN.GE.REL.201.00 | L32: Relazione sui materiali delle opere strutturali | M32: -
B33: ELABORATI GENERALI | C33: 25007 | D33: PE | E33: 2S | F33: GN | G33: GE | H33: REL | I33: 202 | J33: 00 | K33: =CONCATENATE(D33,".",E33,".",F33,".",G33,".",H33,".",I33,".",J33) -> PE.2S.GN.GE.REL.202.00 | L33: Relazione di calcolo delle fondazioni | M33: -
B34: ELABORATI GENERALI | C34: 25007 | D34: PE | E34: 2S | F34: GN | G34: GE | H34: REL | I34: 203 | J34: 00 | K34: =CONCATENATE(D34,".",E34,".",F34,".",G34,".",H34,".",I34,".",J34) -> PE.2S.GN.GE.REL.203.00 | L34: Relazione geotecnica | M34: -
B35: ELABORATI GENERALI | C35: 25007 | D35: PE | E35: 2S | F35: GN | G35: GE | H35: REL | I35: 204 | J35: 00 | K35: =CONCATENATE(D35,".",E35,".",F35,".",G35,".",H35,".",I35,".",J35) -> PE.2S.GN.GE.REL.204.00 | L35: Relazione di calcolo delle opere strutturali | M35: -
B36: ELABORATI GENERALI | C36: 25007 | D36: PE | E36: 2S | F36: GN | G36: GE | H36: REL | I36: 205 | J36: 00 | K36: =CONCATENATE(D36,".",E36,".",F36,".",G36,".",H36,".",I36,".",J36) -> PE.2S.GN.GE.REL.205.00 | L36: Relazione di calcolo delle opere prefabbricate | M36: -
B37: ELABORATI GENERALI | C37: 25007 | D37: PE | E37: 2S | F37: GN | G37: GE | H37: CAP | I37: 206 | J37: 00 | K37: =CONCATENATE(D37,".",E37,".",F37,".",G37,".",H37,".",I37,".",J37) -> PE.2S.GN.GE.CAP.206.00 | L37: Capitolato speciale d'appalto - Parte tecnica - Opere strutturali | M37: -
B38: ELABORATI GENERALI | C38: 25007 | D38: PE | E38: 2S | F38: GN | G38: GE | H38: REL | I38: 207 | J38: 00 | K38: =CONCATENATE(D38,".",E38,".",F38,".",G38,".",H38,".",I38,".",J38) -> PE.2S.GN.GE.REL.207.00 | L38: Piano di manutenzione strutture in opera | M38: -
B39: ELABORATI GENERALI | C39: 25007 | D39: PE | E39: 2S | F39: GN | G39: GE | H39: REL | I39: 208 | J39: 00 | K39: =CONCATENATE(D39,".",E39,".",F39,".",G39,".",H39,".",I39,".",J39) -> PE.2S.GN.GE.REL.208.00 | L39: Piano di manutenzione strutture prefabbricate | M39: -
B40: ELABORATI GENERALI | C40: 25007 | D40: PE | E40: 2S | F40: GN | G40: GE | H40: CME | I40: 209 | J40: 00 | K40: =CONCATENATE(D40,".",E40,".",F40,".",G40,".",H40,".",I40,".",J40) -> PE.2S.GN.GE.CME.209.00 | L40: Computo metrico estimativo - opere strutturali
B41: ELABORATI GENERALI | C41: 25007 | D41: PE | E41: 2S | F41: GN | G41: GE | H41: CME | I41: 210 | J41: 00 | K41: =CONCATENATE(D41,".",E41,".",F41,".",G41,".",H41,".",I41,".",J41) -> PE.2S.GN.GE.CME.210.00 | L41: Quadro di incidenza della manodopera - opere strutturali
B42: ELABORATI GENERALI | C42: 25007 | D42: PE | E42: 2S | F42: GN | G42: GE | H42: EPU | I42: 211 | J42: 00 | K42: =CONCATENATE(D42,".",E42,".",F42,".",G42,".",H42,".",I42,".",J42) -> PE.2S.GN.GE.EPU.211.00 | L42: Elenco ed analisi prezzi unitari - opere strutturali
B43: ELABORATI GENERALI | C43: 25007 | D43: PE | E43: 2S | F43: GN | G43: GE | H43: ELB | I43: 212 | J43: 00 | K43: =CONCATENATE(D43,".",E43,".",F43,".",G43,".",H43,".",I43,".",J43) -> PE.2S.GN.GE.ELB.212.00 | L43: Quadro comparativo: PFTE e PE - opere strutturali
A44: ELABORATI DESCRITTIVI DEGLI IMPIANTI ELETTRICI
...
